<?xml version="1.0" ?>
<robot xmlns:xacro = "http://www.ros.org/wiki/xacro" name="dolly">

  <xacro:macro name="base_inertia" params="m w h d">
    <inertial>
      <mass value="${m}"/>
      <inertia ixx="${m / 12.0 * (d*d + h*h)}" ixy="0.0" ixz="0.0" iyy="${m / 12.0 * (w*w + h*h)}" iyz="0.0" izz="${m / 12.0 * (w*w + d*d)}"/>
    </inertial>
  </xacro:macro>
  <xacro:macro name="cylinder_inertia" params="m r h">
    <inertial>
      <mass value="${m}"/>
      <inertia ixx="${m*(3*r*r+h*h)/12}" ixy = "0" ixz = "0" iyy="${m*(3*r*r+h*h)/12}" iyz = "0" izz="${m*r*r/2}"/> 
    </inertial>
  </xacro:macro>
  <xacro:macro name="sphere_inertia" params="m r">
    <inertial>
      <mass value="${m}"/>
      <inertia ixx="${2.0*m*(r*r)/5.0}" ixy = "0" ixz = "0" iyy="${2.0*m*(r*r)/5.0}" iyz = "0" izz="${2.0*m*(r*r)/5.0}"/> 
    </inertial>
  </xacro:macro>


  <link name="base_link"/>
    

  <joint name="base_joint" type="fixed">
    <parent link="base_link"/>
    <child link="base_footprint" />
    <origin xyz="0 0 0" rpy="0 0 0"/>
  </joint>


  <link name="base_footprint">
    <xacro:base_inertia m="5" w="0.35" h="0.15" d="0.03"/>
     <visual>
      <geometry>
          <box size="0.35 0.2 0.03"/>
      </geometry>
      <material name="gray">
        <color rgba=".2 .2 .2 1" />
      </material>
     </visual>
    
     <collision>
      <geometry>
         <box size="0.35 0.2 0.03"/>
      </geometry>
 
     </collision>
  </link>


  <link name="wheel_right_link">
    <xacro:cylinder_inertia m="5" r="0.0475" h="0.025"/>

    <visual>
      <geometry>
         <cylinder radius="0.0475" length="0.025"/>
      </geometry>
      <material name="white">
        <color rgba="1 1 1 1"/>
      </material>
    </visual>
 
    <collision>
      <geometry>
       <cylinder radius="0.0475" length="0.005"/>
      </geometry>
    </collision>
  </link>
 
  <joint name="wheel_right_joint" type="continuous">
    <origin xyz="0.1 0.115 -0.015" rpy="1.57 0.0 0.0"/>
    <parent link="base_footprint"/>
    <child link="wheel_right_link"/>
    <axis xyz="0.0 0.0 1.0"/>
  </joint>
 
  <link name="wheel_left_link">
    <xacro:cylinder_inertia m="5" r="0.0475" h="0.025"/>
    <visual>
      <geometry>
          <cylinder radius="0.0475" length="0.025"/>
      </geometry>
      <material name="white">
        <color rgba="1 1 1 1"/>
      </material>
    </visual>

    <collision>
      <geometry>
        <cylinder radius="0.0475" length="0.025"/>
      </geometry>
    </collision>
  </link>
 
  <joint name="wheel_left_joint" type="continuous">
    <origin xyz="0.1 -0.115 -0.015" rpy="1.57 0.0 0.0"/>
    <parent link="base_footprint"/>
    <child link="wheel_left_link"/>
    <axis xyz="0.0 0.0 1.0"/>

  </joint>

  <!-- This block connects the wheel joint to an actuator (motor), which informs both
simulation and visualization of the robot -->
<!--########################## BASE TRANSMISSIONS ############################################-->
<transmission name="front_left_wheel_trans" type="SimpleTransmission">
  <type>transmission_interface/SimpleTransmission</type>
  <actuator name="front_left_wheel_motor">
   <hardwareInterface>hardware_interface/VelocityJointInterface</hardwareInterface>
   <mechanicalReduction>1</mechanicalReduction>
  </actuator>
  <joint name="front_left_wheel_joint">
   <hardwareInterface>hardware_interface/VelocityJointInterface</hardwareInterface>
  </joint>
</transmission>

<transmission name="front_right_wheel_trans" type="SimpleTransmission">
  <type>transmission_interface/SimpleTransmission</type>
  <actuator name="front_right_wheel_motor">
   <hardwareInterface>hardware_interface/VelocityJointInterface</hardwareInterface>
   <mechanicalReduction>1</mechanicalReduction>
  </actuator>
  <joint name="front_right_wheel_joint">
   <hardwareInterface>hardware_interface/VelocityJointInterface</hardwareInterface>
  </joint>
</transmission>

<transmission name="rear_left_wheel_trans" type="SimpleTransmission">
  <type>transmission_interface/SimpleTransmission</type>
  <actuator name="rear_left_wheel_motor">
   <hardwareInterface>hardware_interface/VelocityJointInterface</hardwareInterface>
   <mechanicalReduction>1</mechanicalReduction>
  </actuator>
  <joint name="rear_left_wheel_joint">
   <hardwareInterface>hardware_interface/VelocityJointInterface</hardwareInterface>
  </joint>
</transmission>

<transmission name="rear_right_wheel_trans" type="SimpleTransmission">
  <type>transmission_interface/SimpleTransmission</type>
  <actuator name="rear_right_wheel_motor">
   <hardwareInterface>hardware_interface/VelocityJointInterface</hardwareInterface>
   <mechanicalReduction>1</mechanicalReduction>
  </actuator>
  <joint name="rear_right_wheel_joint">
   <hardwareInterface>hardware_interface/VelocityJointInterface</hardwareInterface>
  </joint>
</transmission>

  <link name="caster">
    <xacro:sphere_inertia m="5" r="0.03"/>
    <visual>
      <geometry>
        <sphere radius="0.03" />
      </geometry>
      <material name="white" />
    </visual>

    <collision>
      <geometry>
        <sphere radius="0.03" />
      </geometry>
    </collision>
  </link>

  <joint name="caster_joint" type="continuous">
    <origin xyz="-0.135 0.0 -0.035" rpy="0.0 0.0 0.0"/>
    <axis xyz="0 0 1" />
    <parent link="base_footprint"/>
    <child link="caster"/>
  </joint>
 
 
<!--Front arm-->
<link name="front_arm_bar">
  <visual>
      <geometry>
          <box size="0.025 0.025 0.025"/>
      </geometry>
      <material name="gray">
        <color rgba=".2 .2 .2 1" />
      </material>
  </visual>

  <collision>
    <geometry>
      <box size="0.025 0.025 0.025"/>
    </geometry>
  </collision>

  
  <xacro:base_inertia m="1" w="0.025" h="0.025" d="0.025"/>
</link>
<joint name="front_arm_bar_joint" type="fixed">
  <axis xyz="0.0 1 0.0"/>
  <parent link="base_footprint"/>
  <child link="front_arm_bar"/>
  <origin xyz="-0.187 0.0 -0.0" rpy="0.0 0.0 0.0"/>
</joint>
<!--==========================================================-->

<link name="front_arm_bar_m">
  <visual>
      <geometry>
          <box size="0.004 0.15 0.06"/>
      </geometry>
      <material name="gray">
        <color rgba=".2 .2 .2 1" />
      </material>
  </visual>

  <collision>
    <geometry>
      <box size="0.004 0.15 0.06"/>
    </geometry>
  </collision>
  <xacro:base_inertia m="0.5" w="0.004" h="0.15" d="0.06"/>
</link>
<joint name="front_arm_bar_m_joint" type="fixed">
  <axis xyz="0.0 0 0.0"/>
  <parent link="base_footprint"/>
  <child link="front_arm_bar_m"/>
  <origin xyz="-0.2 0.0 -0.018" rpy="0.0 0.0 0.0"/>
</joint>
<!--==========================================================-->

<link name="front_arm_bar_s1">
  <visual>
      <geometry>
          <box size="0.004 0.08 0.06"/>
      </geometry>
      <material name="gray">
        <color rgba=".2 .2 .2 1" />
      </material>
  </visual>

  <collision>
    <geometry>
      <box size="0.004 0.08 0.06"/>
    </geometry>
  </collision>

  <xacro:base_inertia m="0.5" w="0.004" h="0.08" d="0.06"/>
</link>
<joint name="front_arm_bar_s1_joint" type="fixed">
  <axis xyz="0.0 0 0.0"/>
  <parent link="base_footprint"/>
  <child link="front_arm_bar_s1"/>
  <origin xyz="-0.18 0.105 -0.018" rpy="0 0 -0.55"/>
</joint>
<!--==========================================================-->
 
<link name="front_arm_bar_s2">
  <visual>
      <geometry>
          <box size="0.004 0.08 0.06"/>
      </geometry>
      <material name="gray">
        <color rgba=".2 .2 .2 1" />
      </material>
  </visual>

  <collision>
    <geometry>
      <box size="0.004 0.08 0.06"/>
    </geometry>
  </collision>

  <xacro:base_inertia m="0.5" w="0.004" h="0.08" d="0.06"/>
</link>
<joint name="front_arm_bar_s2_joint" type="fixed">
  <axis xyz="0.0 0 0.0"/>
  <parent link="base_footprint"/>
  <child link="front_arm_bar_s2"/>
  <origin xyz="-0.18 -0.105 -0.018" rpy="0.0 0.0 0.55"/>
</joint>
<!--==========================================================-->

<link name="front_arm_bar_r1">
  <visual>
      <geometry>
          <box size="0.004 0.08 0.06"/>
      </geometry>
      <material name="gray">
        <color rgba=".2 .2 .2 1" />
      </material>
  </visual>

  <collision>
    <geometry>
      <box size="0.004 0.08 0.06"/>
    </geometry>
  </collision>

  <xacro:base_inertia m="0.5" w="0.004" h="0.08" d="0.06"/>
</link>
<joint name="front_arm_bar_r1_joint" type="fixed">
  <axis xyz="0.0 0 0.0"/>
  <parent link="base_footprint"/>
  <child link="front_arm_bar_r1"/>
  <origin xyz="-0.12 -0.138 -0.018" rpy="0.0 0.0 -1.578"/>
</joint>
<!--==========================================================-->
 
<link name="front_arm_bar_r2">
  <visual>
      <geometry>
          <box size="0.004 0.08 0.06"/>
      </geometry>
      <material name="gray">
        <color rgba=".2 .2 .2 1" />
      </material>
  </visual>

  <collision>
    <geometry>
     <box size="0.004 0.08 0.06"/>
    </geometry>
  </collision>

  <xacro:base_inertia m="0.5" w="0.004" h="0.08" d="0.06"/>
</link>
<joint name="front_arm_bar_r2_joint" type="fixed">
  <axis xyz="0.0 0 0.0"/>
  <parent link="base_footprint"/>
  <child link="front_arm_bar_r2"/>
  <origin xyz="-0.12 0.138 -0.018" rpy="0.0 0.0 -1.578"/>
</joint>
<!--==========================================================-->

<!-- laser -->
<link name="laser">
  <xacro:cylinder_inertia m="2" r="0.025" h="0.025"/>

  <visual>
    <geometry>
      <cylinder radius="0.025" length="0.025"/> 
     </geometry>
  </visual>

  <collision>
    <origin/>
    <geometry>
      <cylinder radius="0.025" length="0.025"/> 
    </geometry>
  </collision>
</link>
 
<joint name="laser_joint" type="fixed">
  <origin xyz="0.0505 0.0 0.038" rpy="0.0 0.0 3.14"/>
  <axis xyz="0 0 1" />
  <parent link="base_footprint"/>
  <child link="laser"/>
</joint>

<gazebo reference="laser">
  <sensor type="ray" name="laser">
      <pose>0 0 0 0 0 0</pose>
      <visualize>true</visualize>
      <update_rate>20</update_rate>
      <ray>
          <scan>
              <horizontal>
                  <samples>1440</samples>
                  <resolution>0.5</resolution>
                  <min_angle>-1.578</min_angle>
                  <max_angle>1.578</max_angle>
              </horizontal>
          </scan>
          <range>
            <min>0.10</min>
            <max>3.0</max>
            <resolution>0.01</resolution>
          </range>
          <noise>
            <type>gaussian</type>
            <mean>0.0</mean>
            <stddev>0.01</stddev>
          </noise>
      </ray>
      <plugin name="laser_controller" filename="libgazebo_ros_laser.so">
        
          <topicName>/scan</topicName>
          <frameName>laser</frameName>
      </plugin>
  </sensor>
</gazebo>





 <!-- DIFFENERNTIAL DRIVEEEEEEEEEEEEE -->
 
<gazebo>
    <plugin name="Dolly_bot_controller" filename="libgazebo_ros_diff_drive.so">
      <alwaysOn>false</alwaysOn>
      <legacyMode>false</legacyMode>
      <updateRate>30</updateRate>
      <jointName>caster_joint</jointName>
      <leftJoint>wheel_left_joint</leftJoint>
      <rightJoint>wheel_right_joint</rightJoint>
      <wheelSeparation>0.34</wheelSeparation>
      <wheelDiameter>0.095</wheelDiameter>
      <torque>20</torque>
      <commandTopic>/cmd_vel</commandTopic>
      <robotBaseFrame>base_link</robotBaseFrame>
      <publishWheelJointState>true</publishWheelJointState>
      <wheelAcceleration>2</wheelAcceleration>
      <publishWheelTF>false</publishWheelTF>
  </plugin>
</gazebo>

  <!-- Gazebo colors to links as upper defined colors are only visible in RVIZ-->
  <gazebo reference="base_footprint">
    <material>Gazebo/Orange</material>
  </gazebo>
  <gazebo reference="caster">
    <material>Gazebo/Black</material>
  </gazebo>
  <gazebo reference="wheel_right_link">
    <mu1 value="1.0"/>
    <mu2 value="1.0"/>
    <kp value="10000000.0" />
    <kd value="1.0" />
    <fdir1 value="1 0 0"/>
    <material>Gazebo/Blue</material>
  </gazebo>
  <gazebo reference="wheel_left_link">
    <mu1 value="1.0"/>
    <mu2 value="1.0"/>
    <kp value="10000000.0" />
    <kd value="1.0" />
    <fdir1 value="1 0 0"/>
    <material>Gazebo/Blue</material>
  </gazebo> 
  <gazebo reference="laser">
    <material>Gazebo/Red</material>
  </gazebo> 

  <!--######################################################################-->
<gazebo>
  <plugin name="gazebo_ros_control" filename="libgazebo_ros_control.so">
    <robotNamespace>/</robotNamespace>
    <controlPeriod>0.001</controlPeriod>
    <legacyModeNS>false</legacyModeNS>
  </plugin>
</gazebo>
</robot>